Workbook

Sheet Solar Sizing Calculator
A1: Input Field | B1: Value / Selection | C1: Unit
A2: Productive Use Appliance | B2: Mill 2kW | C2: ←Use Drop Down
A3: System (AC OR DC) | B3: AC | C3: Select One
A4: Runtime per Day | B4: 4 | C4: Hours
A5: Sun hours per day | B5: 4 | C5: Hours
A6: Operating days per year | B6: 250 | C6: (Can be changed)
A7: Solar System In/Out Efficiency | B7: 80 | C7: % (Can be changed)
D9: Should move to Appliance Specs | E9: done
A10: Battery storage hours | B10: 1 | C10: hours
A12: System sizing outputs
A13: Specific Efficiency of Mill | B13: =IFERROR(VLOOKUP(B2,ApplianceSpecs!A:D,4,FALSE)/(B19/1000),"") -> 50 | C13: kg/kWh
A14: Energy Required per Day | B14: =IF(AND(ISNUMBER(B4),ISNUMBER(B19)),B4*B19/1000,"") -> 8 | C14: kWh
A15: Energy Production | B15: =B14/(B7/100) -> 10 | C15: kWh/Day
D16: Move this to first row under Revenue | E16: done
A17: Income Per Day | B17: =B37*B6 -> 8.9285714 | C17: =B37*B14*B13 -> 14.285714 | D17: Wrong formula. Income/day = Income per kg x kg/day = Income/day x kg/kWh x kWh/day | E17: Check This Formula I did in blue and this will also goes under revenue?
A18: Battery Capacity | B18: =IFERROR((B22)*MAX(1,B10),"") -> 2.5 | C18: kWh
A19: Power Rating (Auto) | B19: =IF(B2="","",IFERROR(VLOOKUP(B2,ApplianceSpecs!A:B,2,FALSE),"")) -> 2000 | C19: Watts
D20: Replicated in row 37 so remove it from here, move formula to row 37 | E20: done
A21: Solar Panel Required | B21: =B15/B5 -> 2.5 | C21: Alternate formula on right side➡ | D21: =CEILING((B19*B4)/(ApplianceSpecs!B4*B5), 0.5) -> 4 | E21: I have changed it so it does not round down. But if it sill does we can stick with our default formula.
A22: Recommended Solar System Size | B22: =IF(ISNUMBER(B14), CEILING(B14/4*1.2, 0.5), "") -> 2.5 | C22: kWp (rounded) | D22: Not a good formula. If I put 5 hours per day (B4), it rounds the solar panel size down, should only round up | E22: Check This
A25: Cost estimate | D25: Maybe move Capital Cost Estimate to be before the Revenue section | E25: done
A26: Appliance Cost | B26: =IF(B2="","",IFERROR(VLOOKUP(B2,ApplianceSpecs!A:C,3,FALSE),"")) -> 600
A27: Solar Panel Cost | B27: =CEILING((B22*1000)/ApplianceSpecs!B4,1)*ApplianceSpecs!C4 -> 250
A28: =IF(B3="AC","Solar Inverter",IF(B3="DC","Solar Controller","")) -> Solar Inverter | B28: =IF(B3="AC", VLOOKUP("Solar Inverter", ApplianceSpecs!A:C, 3, FALSE) * B22, IF(B3="DC", VLOOKUP("Solar Controller", ApplianceSpecs!A:C, 3, FALSE), "")) -> 250 | C28: (Changes when AC or DC is selected from above) | E28: AC changes according to system size, DC is same as before
A29: FOB Subtotal | B29: =B26+B27+B32+B28 -> 1850
A30: % cost increase to import and install | B30: 1 | C30: Default 100%, can change.
A31: Installed Capital Cost estimate | B31: =B29*(1+B30) -> 3700
A32: Battery Cost | B32: =B18*ApplianceSpecs!C8 -> 750
A36: Revenue
A37: Income Per Kg | B37: =(5/140) -> 0.035714286 | E37: Moved here
A38: Income per hour | B38: =IFERROR(B37*VLOOKUP(B2,ApplianceSpecs!A:D,4,FALSE),"") -> 3.5714286
A39: Income per day | B39: =B38*B4 -> 14.285714
A40: Gross Income Per Year | B40: =B39*B6 -> 3571.4286
A44: Daily Operating Cost (Expenses)
A45: Daily Operating Cost (Labor, Rent, etc.) | B45: 10 | C45: Can be changed
A46: Net Income Per Day | B46: =IF(OR(B39="",B45=""),"",B39-B45) -> 4.2857143
A48: Financing Inputs
A49: Loan Term (Years) | B49: 3 | C49: Years
A50: Interest Rate (p.a.) | B50: 0.15
A51: Deposit | B51: 0
...

Sheet ApplianceSpecs
A1: Product | B1: Wattage | C1: Price | D1: Processing Speed (kg/hr)
A2: Mill 2kW | B2: 2000 | C2: 600 | D2: 100
A3: Mill 3kW | B3: 3000 | C3: 800 | D3: 150
A4: Solar Panel | B4: 500 | C4: =C5*B4 -> 50
A5: Solar Panel Per Watt | B5: 1 | C5: 0.1
A6: Solar Controller | B6: 1000 | C6: 50
A7: Solar Inverter | B7: 1000 | C7: 100
A8: Battery Cost per kWh | B8: 1000 | C8: 300
A9: Choose any
